Workbook
Name Slicer_City: #N/A
Name Slicer_Department: #N/A
Name Slicer_Education: #N/A
Name Slicer_Gender: #N/A

Sheet DATA
A1: Employee_ID | B1: Name | C1: Age | D1: Gender | E1: Department | F1: Role | G1: Salary | H1: Education | I1: Marital_Status | J1: Join_Date | K1: Tennure_Years | L1: Tennure_Months | M1: Attrition | N1: Performance_Rating | O1: City | P1: Age _Group
A2: EMP1001 | B2: Sneha Sharma | C2: 37 | D2: Male | E2: IT | F2: Intern | G2: 36289 | H2: High School | I2: Divorced | J2: 45471 | K2: =YEAR(TODAY()) - YEAR(J2) -> 1 | L2: =DATEDIF(J2,TODAY(),"YM") -> 5 | M2: Yes | N2: 5 | O2: Kolkata | P2: 36-45
A3: EMP1002 | B3: Rahul Sharma | C3: 25 | D3: Male | E3: IT | F3: Team Lead | G3: 84237 | H3: High School | I3: Divorced | J3: 43252 | K3: =YEAR(TODAY()) - YEAR(J3) -> 7 | L3: =DATEDIF(J3,TODAY(),"YM") -> 6 | M3: No | N3: 2 | O3: Bhubaneswar | P3: 18-25
A4: EMP1003 | B4: Kavya Patel | C4: 20 | D4: Male | E4: R&D | F4: Senior Analyst | G4: 62597 | H4: Diploma | I4: Single | J4: 45565 | K4: =YEAR(TODAY()) - YEAR(J4) -> 1 | L4: =DATEDIF(J4,TODAY(),"YM") -> 2 | M4: No | N4: 1 | O4: Delhi | P4: 18-25
A5: EMP1004 | B5: Tarun Sharma | C5: 42 | D5: Female | E5: Marketing | F5: Intern | G5: 23695 | H5: Masters | I5: Divorced | J5: 42949 | K5: =YEAR(TODAY()) - YEAR(J5) -> 8 | L5: =DATEDIF(J5,TODAY(),"YM") -> 4 | M5: No | N5: 1 | O5: Pune | P5: 36-45
A6: EMP1005 | B6: Kavya Mishra | C6: 43 | D6: Other | E6: IT | F6: Manager | G6: 110349 | H6: High School | I6: Divorced | J6: 43371 | K6: =YEAR(TODAY()) - YEAR(J6) -> 7 | L6: =DATEDIF(J6,TODAY(),"YM") -> 2 | M6: No | N6: 1 | O6: Hyderabad | P6: 36-45
A7: EMP1006 | B7: Sneha Nanda | C7: 37 | D7: Female | E7: Operations | F7: Senior Analyst | G7: 39319 | H7: Bachelors | I7: Single | J7: 45183 | K7: =YEAR(TODAY()) - YEAR(J7) -> 2 | L7: =DATEDIF(J7,TODAY(),"YM") -> 2 | M7: No | N7: 1 | O7: Bengaluru | P7: 36-45
A8: EMP1007 | B8: Karan Singh | C8: 35 | D8: Male | E8: Support | F8: Senior Analyst | G8: 67735 | H8: PhD | I8: Single | J8: 45242 | K8: =YEAR(TODAY()) - YEAR(J8) -> 2 | L8: =DATEDIF(J8,TODAY(),"YM") -> 0 | M8: No | N8: 1 | O8: Hyderabad | P8: 26-35
A9: EMP1008 | B9: Rahul Mishra | C9: 40 | D9: Female | E9: Marketing | F9: Executive | G9: 26675 | H9: PhD | I9: Divorced | J9: 43726 | K9: =YEAR(TODAY()) - YEAR(J9) -> 6 | L9: =DATEDIF(J9,TODAY(),"YM") -> 2 | M9: Yes | N9: 4 | O9: Kolkata | P9: 36-45
A10: EMP1009 | B10: Isha Pradhan | C10: 36 | D10: Male | E10: IT | F10: Team Lead | G10: 115647 | H10: PhD | I10: Married | J10: 45497 | K10: =YEAR(TODAY()) - YEAR(J10) -> 1 | L10: =DATEDIF(J10,TODAY(),"YM") -> 4 | M10: No | N10: 5 | O10: Kolkata | P10: 36-45
A11: EMP1010 | B11: Neha Pradhan | C11: 28 | D11: Other | E11: Support | F11: Associate | G11: 29915 | H11: High School | I11: Single | J11: 43064 | K11: =YEAR(TODAY()) - YEAR(J11) -> 8 | L11: =DATEDIF(J11,TODAY(),"YM") -> 0 | M11: Yes | N11: 4 | O11: Delhi | P11: 26-35
A12: EMP1011 | B12: Tarun Nanda | C12: 58 | D12: Female | E12: Marketing | F12: Associate | G12: 90512 | H12: High School | I12: Divorced | J12: 45390 | K12: =YEAR(TODAY()) - YEAR(J12) -> 1 | L12: =DATEDIF(J12,TODAY(),"YM") -> 8 | M12: Yes | N12: 5 | O12: Pune | P12: 46+
A13: EMP1012 | B13: Neha Sharma | C13: 38 | D13: Female | E13: Finance | F13: Manager | G13: 77470 | H13: Bachelors | I13: Divorced | J13: 45558 | K13: =YEAR(TODAY()) - YEAR(J13) -> 1 | L13: =DATEDIF(J13,TODAY(),"YM") -> 2 | M13: Yes | N13: 5 | O13: Delhi | P13: 36-45
... A1701: EMP2700 | B1701: Tarun Patel | C1701: 28 | D1701: Other | E1701: Marketing | F1701: Junior Analyst | G1701: 54572 | H1701: High School | I1701: Married | J1701: 45863 | K1701: =YEAR(TODAY()) - YEAR(J1701) -> 0 | L1701: =DATEDIF(J1701,TODAY(),"YM") -> 4 | M1701: Yes | N1701: 5 | O1701: Bengaluru | P1701: 26-35

Sheet KPI s
A1: TOTAL EMPLOYESS | C1: Count of Employee_ID
A2: =COUNTA(DATA!A2:A1701) -> 1700 | C2: 1700
A3: TOTAL ATTRITION | C3: Row Labels | D3: Count of Employee_ID
A4: =COUNTIF(DATA!M1:M1701,"YES") -> 876 | C4: No | D4: 824
A5: ATTRITION RATE | C5: Yes | D5: 876
A6: =A4/A2 -> 0.51529412 | C6: Grand Total | D6: 1700
A7: AVERAGE SALARY
A8: =AVERAGE(DATA!G1:G1701) -> 70561.614 | C8: Average of Salary
A9: AVERAGE TENURE | C9: 70561.614
A10: =AVERAGE(DATA!K2:K1701) -> 4.3570588 | C10: Average of Tennure_Years
A11: AVERAGE PERFOMANCE RATING | C11: 4.3570588
A12: =AVERAGE(DATA!N2:N1701) -> 2.9876471 | C12: Average of Performance_Rating
C13: 2.9876471

Sheet PIVOT TABLES 2
A5: Performance_Rating | B5: Count of Employee_ID
A6: 1 | B6: 355
A7: 2 | B7: 330
A8: 3 | B8: 332
A9: 4 | B9: 347
A10: 5 | B10: 336
A11: Grand Total | B11: 1700
A35: Count of Employee_ID | B35: Attrition
A36: Tennure_Years | B36: No | C36: Yes | D36: Grand Total
A37: 0 | B37: 84 | C37: 82 | D37: 166
A38: 1 | B38: 76 | C38: 92 | D38: 168
A39: 2 | B39: 90 | C39: 95 | D39: 185
A40: 3 | B40: 100 | C40: 82 | D40: 182
A41: 4 | B41: 98 | C41: 89 | D41: 187
A42: 5 | B42: 80 | C42: 89 | D42: 169
A43: 6 | B43: 84 | C43: 93 | D43: 177
A44: 7 | B44: 82 | C44: 104 | D44: 186 | W44: Count of Department | X44: Attrition
A45: 8 | B45: 66 | C45: 88 | D45: 154 | W45: Age _Group | X45: No | Y45: Yes | Z45: Grand Total
A46: 9 | B46: 64 | C46: 62 | D46: 126 | W46: 18-25 | X46: 130 | Y46: 143 | Z46: 273
A47: Grand Total | B47: 824 | C47: 876 | D47: 1700 | W47: 26-35 | X47: 200 | Y47: 227 | Z47: 427
W48: 36-45 | X48: 213 | Y48: 238 | Z48: 451
W49: 46+ | X49: 281 | Y49: 268 | Z49: 549
W50: Grand Total | X50: 824 | Y50: 876 | Z50: 1700
A55: Department | B55: Average of Salary
A56: Finance | B56: 68417.869
A57: HR | B57: 70134.703
A58: IT | B58: 73506.875
A59: Marketing | B59: 68027.056
A60: Operations | B60: 70771.342
A61: R&D | B61: 69775.188
A62: Sales | B62: 71795.5
A63: Support | B63: 72114.287
A64: Grand Total | B64: 70561.614
A76: Count of Employee_ID | B76: Attrition
A77: City | B77: No | C77: Yes | D77: Grand Total
A78: Bengaluru | B78: 105 | C78: 121 | D78: 226
A79: Bhubaneswar | B79: 102 | C79: 92 | D79: 194
A80: Chennai | B80: 97 | C80: 92 | D80: 189
A81: Delhi | B81: 108 | C81: 124 | D81: 232
A82: Hyderabad | B82: 109 | C82: 117 | D82: 226
...

Sheet PIVOT TABLES
A3: Count of Employee_ID | B3: Attrition
A4: Department | B4: No | C4: Yes | D4: Grand Total
A5: Finance | B5: 102 | C5: 127 | D5: 229
A6: HR | B6: 99 | C6: 96 | D6: 195
A7: IT | B7: 94 | C7: 106 | D7: 200
A8: Marketing | B8: 94 | C8: 101 | D8: 195
A9: Operations | B9: 101 | C9: 98 | D9: 199
A10: R&D | B10: 104 | C10: 130 | D10: 234
A11: Sales | B11: 114 | C11: 118 | D11: 232
A12: Support | B12: 116 | C12: 100 | D12: 216
A13: Grand Total | B13: 824 | C13: 876 | D13: 1700
A16: Count of Employee_ID | B16: Column Labels
A17: Row Labels | B17: No | C17: Yes | D17: Grand Total
A18: Female | B18: 271 | C18: 282 | D18: 553
A19: Male | B19: 282 | C19: 308 | D19: 590
A20: Other | B20: 271 | C20: 286 | D20: 557
A21: Grand Total | B21: 824 | C21: 876 | D21: 1700

Sheet DASHBOARD
BC4: TOTAL EMPLOYEES
AY5: Count of Employee_ID | BC5: =GETPIVOTDATA("Employee_ID",$AY$5) -> 1700
AY6: 1700
AY9: Row Labels | AZ9: Count of Employee_ID
AY10: No | AZ10: 824
AY11: Yes | AZ11: 876
AY12: Grand Total | AZ12: 1700
J14: =GETPIVOTDATA("Employee_ID",$AY$5) -> 1700 | L14: =GETPIVOTDATA("Employee_ID",$AY$9,"Attrition","Yes") -> 876 | P14: =L14/J14 -> 0.51529412 | AA14: =GETPIVOTDATA("Performance_Rating",$AY$20) -> 2.9876471 | AY14: Average of Salary
P15: =P14 -> 0.51529412 | S15: =GETPIVOTDATA("Salary",$AY$14) -> 70561.614 | X15: =GETPIVOTDATA("Tennure_Years",$AY$17) -> 4.3570588 | AY15: 70561.614
AY17: Average of Tennure_Years
AY18: 4.3570588
AY20: Average of Performance_Rating
AY21: 2.9876471
